Workbook
Name Année: 'Listes déroulantes, autres'!$D$9:$D$4979
Name CO2_: #REF!,#REF!,#REF!,#REF!,#REF!
Name Debut_1A1: Calculs!$B$10
Name Équipements_fixes: FÉ!$B$9:$B$21
Name Équipements_mobiles: FÉ!$B$41:$B$59
Name Fin_1A1: Calculs!$B$31
Name Grid: FÉ!$B$385:$B$437
Name Intensité_type_bâtiments: FÉ!$B$26:$B$36
Name Liste_Véhicules_Compagnie: 'Détails Entreprise'!$O$9:$O$20
Name Marque: 'Listes déroulantes, autres'!$E$9:$E$4979
Name Modèle: 'Listes déroulantes, autres'!$F$9:$F$4979
Name Moyennes_de_transport: FÉ!$B$64:$B$74
Name Oui_Non: 'Listes déroulantes, autres'!$C$9:$C$10
Name Sites: #REF!,#REF!,#REF!,#REF!,#REF!
Name Transmission: 'Listes déroulantes, autres'!$G$9:$G$10

Sheet Page d'accueil
C4: Back-end du logiciel d'inventaire GES
C5: Logiciel co-produit par la collaboration de Carbone Québec et i-GES
C6: Version 2.1.0
E14: Contact i-GES
E15: Pierre-Emile Leblanc Comtois
E16: pe.leblanc-comtois@i-ges.ca
E17: Sherbrooke, Qc
C19: Ce calculateur permet de se conformer à la norme ISO 14064-1. | M19: Tous droits réservés 2025
B21: Mises à jours
B22: Mise à jour | C22: date | D22: Description
B23: 2.1.0 | C23: 45992 | D23: - Réorganisation des postes d'émissions pour répondre à la nouvelle norme ISO 14064-4 (2025) "Application de la norme ISO 14064-1 (2013)" sortie en novembre 2025.

Sheet ISO 14064-4
B2: Bilan (Détaillé par catégorie) | Q2: CO2 Biogénique | S2: État d'inventaire
B3: Categorie | I3: Description | J3: CO2 [tCO2e] | K3: CH4 [tCO2e] | L3: N2O [tCO2e] | M3: Total tCO2e | N3: % | O3: Bar %
B4: Catégorie 1 | D4: Émissions directs | I4: Émissions directes | J4: =SUMIFS(J$42:J$154,$C$42:$C$154,$B4) -> 13.252841 | K4: =SUMIFS(K$42:K$154,$C$42:$C$154,$B4) -> 0.090484535 | L4: =SUMIFS(L$42:L$154,$C$42:$C$154,$B4) -> 0.094192804 | M4: =SUMIFS(M$42:M$154,$C$42:$C$154,$B4) -> 20.371226 | N4: =M4/$M$10 -> 0.11470822 | O4: =REPT("|",N4*(100/MAX($N$4:$N$9))) -> |||||||||||||||||| | Q4: =SUMIFS(Q$42:Q$154,$C$42:$C$154,$B4) -> 2.6985
B5: Catégorie 2 | D5: Émissions indirects de l'énergie importée | I5: Émissions indirectes liées à l'énergie importée | J5: =SUMIFS(J$42:J$154,$C$42:$C$154,$B5) -> 27.880882 | K5: =SUMIFS(K$42:K$154,$C$42:$C$154,$B5) -> 0.016389352 | L5: =SUMIFS(L$42:L$154,$C$42:$C$154,$B5) -> 0.13090095 | M5: =SUMIFS(M$42:M$154,$C$42:$C$154,$B5) -> 28.028172 | N5: =M5/$M$10 -> 0.15782368 | O5: =REPT("|",N5*(100/MAX($N$4:$N$9))) -> ||||||||||||||||||||||||| | Q5: =SUMIFS(Q$42:Q$154,$C$42:$C$154,$B5) -> 0
B6: Catégorie 3 | D6: Émissions indirects des transports | I6: Émissions indirectes des déplacements et des transports | J6: =SUMIFS(J$42:J$154,$C$42:$C$154,$B6) -> 19.802851 | K6: =SUMIFS(K$42:K$154,$C$42:$C$154,$B6) -> 0.014693907 | L6: =SUMIFS(L$42:L$154,$C$42:$C$154,$B6) -> 0.19019935 | M6: =SUMIFS(M$42:M$154,$C$42:$C$154,$B6) -> 20.007745 | N6: =M6/$M$10 -> 0.1126615 | O6: =REPT("|",N6*(100/MAX($N$4:$N$9))) -> |||||||||||||||||| | Q6: =SUMIFS(Q$42:Q$154,$C$42:$C$154,$B6) -> 0
B7: Catégorie 4 | D7: Émissions indirects des produits utilisés par l'organisation | I7: Émissions indirectes en amont (Biens et services, locations en amonts) | J7: =SUMIFS(J$42:J$154,$C$42:$C$154,$B7) -> 109.16114 | K7: =SUMIFS(K$42:K$154,$C$42:$C$154,$B7) -> 0.023397962 | L7: =SUMIFS(L$42:L$154,$C$42:$C$154,$B7) -> 0 | M7: =SUMIFS(M$42:M$154,$C$42:$C$154,$B7) -> 109.18453 | N7: =M7/$M$10 -> 0.61480659 | O7: =REPT("|",N7*(100/MAX($N$4:$N$9))) -> |||||||||||||||||||||||||||||||||||||||||||||||||||||||||||||||||||||||||||||||||||||||||||||||||||| | Q7: =SUMIFS(Q$42:Q$154,$C$42:$C$154,$B7) -> 0
B8: Catégorie 5 | D8: Émissions indirects à l'utilisation des produits de l'organisation | I8: Émissions indirectes en aval (Usage et fin de vie des produits, franchises et investissement) | J8: =SUMIFS(J$42:J$154,$C$42:$C$154,$B8) -> 0 | K8: =SUMIFS(K$42:K$154,$C$42:$C$154,$B8) -> 0 | L8: =SUMIFS(L$42:L$154,$C$42:$C$154,$B8) -> 0 | M8: =SUMIFS(M$42:M$154,$C$42:$C$154,$B8) -> 0 | N8: =M8/$M$10 -> 0 | O8: =REPT("|",N8*(100/MAX($N$4:$N$9))) | Q8: =SUMIFS(Q$42:Q$154,$C$42:$C$154,$B8) -> 0
B9: Catégorie 6 | D9: Autres émissions indirects | I9: Autres sources d'émissions indirectes | J9: =SUMIFS(J$42:J$154,$C$42:$C$154,$B9) -> 0 | K9: =SUMIFS(K$42:K$154,$C$42:$C$154,$B9) -> 0 | L9: =SUMIFS(L$42:L$154,$C$42:$C$154,$B9) -> 0 | M9: =SUMIFS(M$42:M$154,$C$42:$C$154,$B9) -> 0 | N9: =M9/$M$10 -> 0 | O9: =REPT("|",N9*(100/MAX($N$4:$N$9))) | Q9: =SUMIFS(Q$42:Q$154,$C$42:$C$154,$B9) -> 0
I10: Totaux : | J10: =SUM(J4:J9) -> 170.09771 | K10: =SUM(K4:K9) -> 0.14496576 | L10: =SUM(L4:L9) -> 0.41529311 | M10: =SUM(M4:M9) -> 177.59168 | N10: tCO2e | Q10: =SUM(Q4:Q9) -> 2.6985
B12: Bilan (Détaillé par poste d'émissions) | Q12: CO2 Biogénique | S12: État d'inventaire
B13: Categorie | E13: Poste d'émissions | I13: Description | J13: CO2 [tCO2e] | K13: CH4 [tCO2e] | L13: N2O [tCO2e] | M13: Total tCO2e | N13: % | O13: Bar %
B14: Catégorie 1 | D14: Émissions directs | E14: 1.1 | G14: Combustions fixes | I14: Émissions directes des sources de combustions fixes | J14: =SUMIFS(J$42:J$154,$F$42:$F$154,$E14) -> 4.268 | K14: =SUMIFS(K$42:K$154,$F$42:$F$154,$E14) -> 0.0319158 | L14: =SUMIFS(L$42:L$154,$F$42:$F$154,$E14) -> 0.0694785 | M14: =SUMIFS(M$42:M$154,$F$42:$F$154,$E14) -> 4.3693943 | N14: =M14/$M$36 -> 0.024603598 | O14: =REPT("|",N14*(100/MAX($N$14:$N$35))) -> |||| | Q14: =SUMIFS(Q$42:Q$154,$F$42:$F$154,$E14) -> 2.6985
E15: 1.2 | G15: Combustions mobiles | I15: Émissions directes des sources de combustions mobiles | J15: =SUMIFS(J$42:J$154,$F$42:$F$154,$E15) -> 8.9848405 | K15: =SUMIFS(K$42:K$154,$F$42:$F$154,$E15) -> 0.058568735 | L15: =SUMIFS(L$42:L$154,$F$42:$F$154,$E15) -> 0.024714304 | M15: =SUMIFS(M$42:M$154,$F$42:$F$154,$E15) -> 9.0681236 | N15: =M15/$M$36 -> 0.051061647 | O15: =REPT("|",N15*(100/MAX($N$14:$N$35))) -> |||||||| | Q15: =SUMIFS(Q$42:Q$154,$F$42:$F$154,$E15) -> 0
E16: 1.3 | G16: Procédés | I16: Émissions directes provenant des procédés et élevages d'animaux | J16: =SUMIFS(J$42:J$154,$F$42:$F$154,$E16) -> 0 | K16: =SUMIFS(K$42:K$154,$F$42:$F$154,$E16) -> 0 | L16: =SUMIFS(L$42:L$154,$F$42:$F$154,$E16) -> 0 | M16: =SUMIFS(M$42:M$154,$F$42:$F$154,$E16) -> 0 | N16: =M16/$M$36 -> 0 | O16: =REPT("|",N16*(100/MAX($N$14:$N$35))) | Q16: =SUMIFS(Q$42:Q$154,$F$42:$F$154,$E16) -> 0
E17: 1.4 | G17: Émissions fugitives | I17: Émissions fugitives directes (Réfrigérants) | J17: =SUMIFS(J$42:J$154,$F$42:$F$154,$E17) -> 0 | K17: =SUMIFS(K$42:K$154,$F$42:$F$154,$E17) -> 0 | L17: =SUMIFS(L$42:L$154,$F$42:$F$154,$E17) -> 0 | M17: =SUMIFS(M$42:M$154,$F$42:$F$154,$E17) -> 6.9337082 | N17: =M17/$M$36 -> 0.039042979 | O17: =REPT("|",N17*(100/MAX($N$14:$N$35))) -> |||||| | Q17: =SUMIFS(Q$42:Q$154,$F$42:$F$154,$E17) -> 0
E18: 1.5 | G18: Usage des sols | I18: Émissions directes provenant de l'usage des sols (incluant agricoles) et de la foresterie | J18: =SUMIFS(J$42:J$154,$F$42:$F$154,$E18) -> 0 | K18: =SUMIFS(K$42:K$154,$F$42:$F$154,$E18) -> 0 | L18: =SUMIFS(L$42:L$154,$F$42:$F$154,$E18) -> 0 | M18: =SUMIFS(M$42:M$154,$F$42:$F$154,$E18) -> 0 | N18: =M18/$M$36 -> 0 | O18: =REPT("|",N18*(100/MAX($N$14:$N$35))) | Q18: =SUMIFS(Q$42:Q$154,$F$42:$F$154,$E18) -> 0
B19: Catégorie 2 | D19: Émissions indirects de l'énergie importée | E19: 2.1 | G19: Électricités | I19: Émissions indirectes provenant de la consommation d'électricité | J19: =SUMIFS(J$42:J$154,$F$42:$F$154,$E19) -> 1.5888821 | K19: =SUMIFS(K$42:K$154,$F$42:$F$154,$E19) -> 0.00095295221 | L19: =SUMIFS(L$42:L$154,$F$42:$F$154,$E19) -> 0.00095295221 | M19: =SUMIFS(M$42:M$154,$F$42:$F$154,$E19) -> 1.590788 | N19: =M19/$M$36 -> 0.0089575592 | O19: =REPT("|",N19*(100/MAX($N$14:$N$35))) -> | | Q19: =SUMIFS(Q$42:Q$154,$F$42:$F$154,$E19) -> 0
E20: 2.2 | G20: Autres énergies importées | I20: Émissions indirectes provenant de la consommation d'un réseau d'énergie (exclut l'électricité) | J20: =SUMIFS(J$42:J$154,$F$42:$F$154,$E20) -> 26.292 | K20: =SUMIFS(K$42:K$154,$F$42:$F$154,$E20) -> 0.0154364 | L20: =SUMIFS(L$42:L$154,$F$42:$F$154,$E20) -> 0.129948 | M20: =SUMIFS(M$42:M$154,$F$42:$F$154,$E20) -> 26.437384 | N20: =M20/$M$36 -> 0.14886612 | O20: =REPT("|",N20*(100/MAX($N$14:$N$35))) -> |||||||||||||||||||||||| | Q20: =SUMIFS(Q$42:Q$154,$F$42:$F$154,$E20) -> 0
B21: Catégorie 3 | D21: Émissions indirects des transports | E21: 3.1 | G21: Transport en amont | I21: Transport et distribution en amont | J21: =SUMIFS(J$42:J$154,$F$42:$F$154,$E21) -> 0 | K21: =SUMIFS(K$42:K$154,$F$42:$F$154,$E21) -> 0 | L21: =SUMIFS(L$42:L$154,$F$42:$F$154,$E21) -> 0 | M21: =SUMIFS(M$42:M$154,$F$42:$F$154,$E21) -> 0 | N21: =M21/$M$36 -> 0 | O21: =REPT("|",N21*(100/MAX($N$14:$N$35))) | Q21: =SUMIFS(Q$42:Q$154,$F$42:$F$154,$E21) -> 0
E22: 3.2 | G22: Transport en aval | I22: Transport et distribution des produits en aval | J22: =SUMIFS(J$42:J$154,$F$42:$F$154,$E22) -> 0 | K22: =SUMIFS(K$42:K$154,$F$42:$F$154,$E22) -> 0 | L22: =SUMIFS(L$42:L$154,$F$42:$F$154,$E22) -> 0 | M22: =SUMIFS(M$42:M$154,$F$42:$F$154,$E22) -> 0 | N22: =M22/$M$36 -> 0 | O22: =REPT("|",N22*(100/MAX($N$14:$N$35))) | Q22: =SUMIFS(Q$42:Q$154,$F$42:$F$154,$E22) -> 0
E23: 3.3 | G23: Navettage des employés | I23: Navettage des employés | J23: =SUMIFS(J$42:J$154,$F$42:$F$154,$E23) -> 5.3790753 | K23: =SUMIFS(K$42:K$154,$F$42:$F$154,$E23) -> 0.009721809 | L23: =SUMIFS(L$42:L$154,$F$42:$F$154,$E23) -> 0.014100091 | M23: =SUMIFS(M$42:M$154,$F$42:$F$154,$E23) -> 5.4028972 | N23: =M23/$M$36 -> 0.030423144 | O23: =REPT("|",N23*(100/MAX($N$14:$N$35))) -> |||| | Q23: =SUMIFS(Q$42:Q$154,$F$42:$F$154,$E23) -> 0
E24: 3.4 | G24: Déplacement des clients | I24: Déplacements des clients et des visiteurs | J24: =SUMIFS(J$42:J$154,$F$42:$F$154,$E24) -> 6.89053 | K24: =SUMIFS(K$42:K$154,$F$42:$F$154,$E24) -> 0.0020442082 | L24: =SUMIFS(L$42:L$154,$F$42:$F$154,$E24) -> 0.085885023 | M24: =SUMIFS(M$42:M$154,$F$42:$F$154,$E24) -> 6.9784593 | N24: =M24/$M$36 -> 0.039294968 | O24: =REPT("|",N24*(100/MAX($N$14:$N$35))) -> |||||| | Q24: =SUMIFS(Q$42:Q$154,$F$42:$F$154,$E24) -> 0
E25: 3.5 | G25: Déplacement d'affaires | I25: Déplacements d'affaires | J25: =SUMIFS(J$42:J$154,$F$42:$F$154,$E25) -> 7.5332462 | K25: =SUMIFS(K$42:K$154,$F$42:$F$154,$E25) -> 0.0029278893 | L25: =SUMIFS(L$42:L$154,$F$42:$F$154,$E25) -> 0.090214239 | M25: =SUMIFS(M$42:M$154,$F$42:$F$154,$E25) -> 7.6263883 | N25: =M25/$M$36 -> 0.042943388 | O25: =REPT("|",N25*(100/MAX($N$14:$N$35))) -> |||||| | Q25: =SUMIFS(Q$42:Q$154,$F$42:$F$154,$E25) -> 0
B26: Catégorie 4 | D26: Émissions indirects des produits utilisés par l'organisation | E26: 4.1 | G26: Biens et matière première | I26: Biens, matière première et énergie | J26: =SUMIFS(J$42:J$154,$F$42:$F$154,$E26) -> 109.16114 | K26: =SUMIFS(K$42:K$154,$F$42:$F$154,$E26) -> 0 | L26: =SUMIFS(L$42:L$154,$F$42:$F$154,$E26) -> 0 | M26: =SUMIFS(M$42:M$154,$F$42:$F$154,$E26) -> 109.16114 | N26: =M26/$M$36 -> 0.61467484 | O26: =REPT("|",N26*(100/MAX($N$14:$N$35))) -> |||||||||||||||||||||||||||||||||||||||||||||||||||||||||||||||||||||||||||||||||||||||||||||||||||| | Q26: =SUMIFS(Q$42:Q$154,$F$42:$F$154,$E26) -> 0
E27: 4.2 | G27: Biens immobiliés | I27: Biens immobiliers | J27: =SUMIFS(J$42:J$154,$F$42:$F$154,$E27) -> 0 | K27: =SUMIFS(K$42:K$154,$F$42:$F$154,$E27) -> 0 | L27: =SUMIFS(L$42:L$154,$F$42:$F$154,$E27) -> 0 | M27: =SUMIFS(M$42:M$154,$F$42:$F$154,$E27) -> 0 | N27: =M27/$M$36 -> 0 | O27: =REPT("|",N27*(100/MAX($N$14:$N$35))) | Q27: =SUMIFS(Q$42:Q$154,$F$42:$F$154,$E27) -> 0
E28: 4.3 | G28: Déchets | I28: Déchets | J28: =SUMIFS(J$42:J$154,$F$42:$F$154,$E28) -> 0 | K28: =SUMIFS(K$42:K$154,$F$42:$F$154,$E28) -> 0.023397962 | L28: =SUMIFS(L$42:L$154,$F$42:$F$154,$E28) -> 0 | M28: =SUMIFS(M$42:M$154,$F$42:$F$154,$E28) -> 0.023397962 | N28: =M28/$M$36 -> 0.00013175146 | O28: =REPT("|",N28*(100/MAX($N$14:$N$35))) | Q28: =SUMIFS(Q$42:Q$154,$F$42:$F$154,$E28) -> 0
E29: 4.4 | G29: Location d'actifs en amont | I29: Location d'actif en amont | J29: =SUMIFS(J$42:J$154,$F$42:$F$154,$E29) -> 0 | K29: =SUMIFS(K$42:K$154,$F$42:$F$154,$E29) -> 0 | L29: =SUMIFS(L$42:L$154,$F$42:$F$154,$E29) -> 0 | M29: =SUMIFS(M$42:M$154,$F$42:$F$154,$E29) -> 0 | N29: =M29/$M$36 -> 0 | O29: =REPT("|",N29*(100/MAX($N$14:$N$35))) | Q29: =SUMIFS(Q$42:Q$154,$F$42:$F$154,$E29) -> 0
E30: 4.5 | G30: Services | I30: Services | J30: =SUMIFS(J$42:J$154,$F$42:$F$154,$E30) -> 0 | K30: =SUMIFS(K$42:K$154,$F$42:$F$154,$E30) -> 0 | L30: =SUMIFS(L$42:L$154,$F$42:$F$154,$E30) -> 0 | M30: =SUMIFS(M$42:M$154,$F$42:$F$154,$E30) -> 0 | N30: =M30/$M$36 -> 0 | O30: =REPT("|",N30*(100/MAX($N$14:$N$35))) | Q30: =SUMIFS(Q$42:Q$154,$F$42:$F$154,$E30) -> 0
B31: Catégorie5 | D31: Émissions indirects à l'utilisation des produits de l'organisation | E31: 5.1 | G31: Utilisation des produits | I31: Utilisation des produits vendus | J31: =SUMIFS(J$42:J$154,$F$42:$F$154,$E31) -> 0 | K31: =SUMIFS(K$42:K$154,$F$42:$F$154,$E31) -> 0 | L31: =SUMIFS(L$42:L$154,$F$42:$F$154,$E31) -> 0 | M31: =SUMIFS(M$42:M$154,$F$42:$F$154,$E31) -> 0 | N31: =M31/$M$36 -> 0 | O31: =REPT("|",N31*(100/MAX($N$14:$N$35))) | Q31: =SUMIFS(Q$42:Q$154,$F$42:$F$154,$E31) -> 0
E32: 5.2 | G32: Location d'actifs en aval | I32: Location d'actif en aval | J32: =SUMIFS(J$42:J$154,$F$42:$F$154,$E32) -> 0 | K32: =SUMIFS(K$42:K$154,$F$42:$F$154,$E32) -> 0 | L32: =SUMIFS(L$42:L$154,$F$42:$F$154,$E32) -> 0 | M32: =SUMIFS(M$42:M$154,$F$42:$F$154,$E32) -> 0 | N32: =M32/$M$36 -> 0 | O32: =REPT("|",N32*(100/MAX($N$14:$N$35))) | Q32: =SUMIFS(Q$42:Q$154,$F$42:$F$154,$E32) -> 0
E33: 5.3 | G33: Fin de vie des produits | I33: Fin de vie des produits | J33: =SUMIFS(J$42:J$154,$F$42:$F$154,$E33) -> 0 | K33: =SUMIFS(K$42:K$154,$F$42:$F$154,$E33) -> 0 | L33: =SUMIFS(L$42:L$154,$F$42:$F$154,$E33) -> 0 | M33: =SUMIFS(M$42:M$154,$F$42:$F$154,$E33) -> 0 | N33: =M33/$M$36 -> 0 | O33: =REPT("|",N33*(100/MAX($N$14:$N$35))) | Q33: =SUMIFS(Q$42:Q$154,$F$42:$F$154,$E33) -> 0
E34: 5.4 | G34: Investissements | I34: Investissement | J34: =SUMIFS(J$42:J$154,$F$42:$F$154,$E34) -> 0 | K34: =SUMIFS(K$42:K$154,$F$42:$F$154,$E34) -> 0 | L34: =SUMIFS(L$42:L$154,$F$42:$F$154,$E34) -> 0 | M34: =SUMIFS(M$42:M$154,$F$42:$F$154,$E34) -> 0 | N34: =M34/$M$36 -> 0 | O34: =REPT("|",N34*(100/MAX($N$14:$N$35))) | Q34: =SUMIFS(Q$42:Q$154,$F$42:$F$154,$E34) -> 0
B35: Catégorie 6 | D35: Autres émissions indirects | E35: 6 | G35: Autres | I35: Autres | J35: =SUMIFS(J$42:J$154,$F$42:$F$154,$E35) -> 0 | K35: =SUMIFS(K$42:K$154,$F$42:$F$154,$E35) -> 0 | L35: =SUMIFS(L$42:L$154,$F$42:$F$154,$E35) -> 0 | M35: =SUMIFS(M$42:M$154,$F$42:$F$154,$E35) -> 0 | N35: =M35/$M$36 -> 0 | O35: =REPT("|",N35*(100/MAX($N$14:$N$35))) | Q35: =SUMIFS(Q$42:Q$154,$F$42:$F$154,$E35) -> 0
I36: Totaux : | J36: =SUM(J14:J35) -> 170.09771 | K36: =SUM(K14:K35) -> 0.14496576 | L36: =SUM(L14:L35) -> 0.41529311 | M36: =SUM(M14:M35) -> 177.59168 | N36: tCO2e | Q36: =SUM(Q14:Q35) -> 2.6985
B38: Bilan (Détaillé par méthodologie) | Q38: CO2 Biogénique | S38: État d'inventaire | V38: Bilan détaillé par mois, site et/ou produit
V39: Mois | W39: Site | X39: Produit ou service
V40: Tous | W40: Bureau | X40: Tous
B41: Categorie | E41: Sous-catégorie | H41: # de méthode | I41: Description | J41: CO2 [tCO2e] | K41: CH4 [tCO2e] | L41: N2O [tCO2e] | M41: Total tCO2e | N41: % | O41: Bar % | W41: Total tCO2e | X41: % | Y41: Bar %
B42: Catégorie 1 | C42: =IF(B42=0,C41,B42) -> Catégorie 1 | D42: Émissions directs | E42: 1.1 | F42: =IF(E42=0,F41,E42) -> 1.1 | G42: Combustions fixes | H42: 1.1A1 | I42: =Calculs!B5 -> 1.1A1 - Chauffage des bâtiments et équipements fixes | J42: =SUMIFS(Calculs!BY$11:BY$1338,Calculs!$B$11:$B$1338,$H42)/10^6 -> 4.268 | K42: =SUMIFS(Calculs!BZ$11:BZ$1338,Calculs!$B$11:$B$1338,$H42)/10^6 -> 0.0319158 | L42: =SUMIFS(Calculs!CA$11:CA$1338,Calculs!$B$11:$B$1338,$H42)/10^6 -> 0.0694785 | M42: =SUMIFS(Calculs!CB$11:CB$1338,Calculs!$B$11:$B$1338,$H42)/10^6 -> 4.3693943 | N42: =M42/$M$155 -> 0.024603598 | O42: =REPT("|",N42*(100/MAX($N$14:$N$35))) -> |||| | Q42: =Calculs!CF31 -> 2.6985 | W42: =(SUMIFS(Calculs!CB$11:CB$1338,Calculs!$B$11:$B$1338,$H42,Calculs!$F$11:$F$1338,IF($V$40="Tous","<>0",VLOOKUP($V$40,'Listes déroulantes, autres'!$H$9:$I$21,2,FALSE)),Calculs!$G$11:$G$1338,IF($W$40="Tous","<>0",$W$40),Calculs!$H$11:$H$1338,IF($X$40="Tous","<>0",$X$40) )/10^6) -> 0.0572787 | X42: =W42/$M$155 -> 0.00032253032 | Y42: =REPT("|",X42*(100/MAX($N$14:$N$35)))
C43: =IF(B43=0,C42,B43) -> Catégorie 1 | F43: =IF(E43=0,F42,E43) -> 1.1 | H43: 1.1A2 | J43: =SUMIFS(Calculs!BY$11:BY$1338,Calculs!$B$11:$B$1338,$H43)/10^6 -> 0 | K43: =SUMIFS(Calculs!BZ$11:BZ$1338,Calculs!$B$11:$B$1338,$H43)/10^6 -> 0 | L43: =SUMIFS(Calculs!CA$11:CA$1338,Calculs!$B$11:$B$1338,$H43)/10^6 -> 0 | M43: =SUMIFS(Calculs!CB$11:CB$1338,Calculs!$B$11:$B$1338,$H43)/10^6 -> 0 | N43: =M43/$M$155 -> 0 | O43: =REPT("|",N43*(100/MAX($N$14:$N$35))) | W43: =(SUMIFS(Calculs!CB$11:CB$1338,Calculs!$B$11:$B$1338,$H43,Calculs!$F$11:$F$1338,IF($V$40="Tous","<>0",VLOOKUP($V$40,'Listes déroulantes, autres'!$H$9:$I$21,2,FALSE)),Calculs!$G$11:$G$1338,IF($W$40="Tous","<>0",$W$40),Calculs!$H$11:$H$1338,IF($X$40="Tous","<>0",$X$40) )/10^6) -> 0 | X43: =W43/$M$155 -> 0 | Y43: =REPT("|",X43*(100/MAX($N$14:$N$35)))
...

Sheet GHG Protocol

Sheet MACF-CBAM

Sheet Détails Entreprise
B2: Détails sur l'entreprise et ses actifs
B4: Nom de l'entreprise : | C4: EntrepTest
B5: Adresse de la maison mère : | C5: 1234 St-Montréal road, Saguenay
B7: Liste des lieux de production | H7: Produits et services | O7: Liste de la flotte de véhicule
B8: Nom du lieu | C8: Description | D8: Adresse | E8: GES par Site [tCO2e] | H8: Nom du produit ou service | I8: Description | J8: GES par unité [kgCO2e/unité] | K8: Quantité | L8: unité | M8: GES pour toute la game de produit [tCO2e] | O8: Nom ou numéro du véhicule | P8: Année | Q8: Marque | R8: Modèle | S8: Type de véhicule | T8: Climatisation
B9: Bureau | D9: 1234 St-Montréal road, Saguenay | E9: =SUMIFS(Calculs!$CC$11:$CC$1338,Calculs!$G$11:$G$1338,$B9) -> 60.851452 | H9: Nettoyage | I9: Service de nettoyage | J9: =IF(K9=0,,M9*1000/(K9)) -> 0.54363265 | K9: 2500 | L9: h | M9: =SUMIFS(Calculs!$CC$11:$CC$1338,Calculs!$H$11:$H$1338,$H9) -> 1.3590816 | O9: Petit camion #1 | S9: Camion léger - Essence [L] | T9: Oui
B10: Usine #1 | D10: 555 boul. industriel | E10: =SUMIFS(Calculs!$CC$11:$CC$1338,Calculs!$G$11:$G$1338,$B10) -> 64.164545 | H10: Balais | I10: Fabrication de balais | J10: =IF(K10=0,,M10*1000/(K10)) -> 6.5104525 | K10: 1500 | L10: nb | M10: =SUMIFS(Calculs!$CC$11:$CC$1338,Calculs!$H$11:$H$1338,$H10) -> 9.7656788 | O10: Gros camion #2 | S10: Camion lourd - Diesel [L] | T10: Oui
B11: Usine #2 | D11: 556 boul. Industriel | E11: =SUMIFS(Calculs!$CC$11:$CC$1338,Calculs!$G$11:$G$1338,$B11) -> 29.713885 | J11: =IF(K11=0,,M11*1000/(K11)) -> 0 | M11: =SUMIFS(Calculs!$CC$11:$CC$1338,Calculs!$H$11:$H$1338,$H11) -> 0
B12: Shop | D12: 111 rue principale | E12: =SUMIFS(Calculs!$CC$11:$CC$1338,Calculs!$G$11:$G$1338,$B12) -> 17.972081 | J12: =IF(K12=0,,M12*1000/(K12)) -> 0 | M12: =SUMIFS(Calculs!$CC$11:$CC$1338,Calculs!$H$11:$H$1338,$H12) -> 0
E13: =SUMIFS(Calculs!$CC$11:$CC$1338,Calculs!$G$11:$G$1338,$B13) -> 0 | J13: =IF(K13=0,,M13*1000/(K13)) -> 0 | M13: =SUMIFS(Calculs!$CC$11:$CC$1338,Calculs!$H$11:$H$1338,$H13) -> 0
E14: =SUMIFS(Calculs!$CC$11:$CC$1338,Calculs!$G$11:$G$1338,$B14) -> 0 | J14: =IF(K14=0,,M14*1000/(K14)) -> 0 | M14: =SUMIFS(Calculs!$CC$11:$CC$1338,Calculs!$H$11:$H$1338,$H14) -> 0
E15: =SUMIFS(Calculs!$CC$11:$CC$1338,Calculs!$G$11:$G$1338,$B15) -> 0 | J15: =IF(K15=0,,M15*1000/(K15)) -> 0 | M15: =SUMIFS(Calculs!$CC$11:$CC$1338,Calculs!$H$11:$H$1338,$H15) -> 0
E16: =SUMIFS(Calculs!$CC$11:$CC$1338,Calculs!$G$11:$G$1338,$B16) -> 0 | J16: =IF(K16=0,,M16*1000/(K16)) -> 0 | M16: =SUMIFS(Calculs!$CC$11:$CC$1338,Calculs!$H$11:$H$1338,$H16) -> 0
E17: =SUMIFS(Calculs!$CC$11:$CC$1338,Calculs!$G$11:$G$1338,$B17) -> 0 | J17: =IF(K17=0,,M17*1000/(K17)) -> 0 | M17: =SUMIFS(Calculs!$CC$11:$CC$1338,Calculs!$H$11:$H$1338,$H17) -> 0
E18: =SUMIFS(Calculs!$CC$11:$CC$1338,Calculs!$G$11:$G$1338,$B18) -> 0 | J18: =IF(K18=0,,M18*1000/(K18)) -> 0 | M18: =SUMIFS(Calculs!$CC$11:$CC$1338,Calculs!$H$11:$H$1338,$H18) -> 0
E19: =SUMIFS(Calculs!$CC$11:$CC$1338,Calculs!$G$11:$G$1338,$B19) -> 0 | J19: =IF(K19=0,,M19*1000/(K19)) -> 0 | M19: =SUMIFS(Calculs!$CC$11:$CC$1338,Calculs!$H$11:$H$1338,$H19) -> 0
B20: ="" | C20: GES non attribué | E20: =SUMIFS(Calculs!$CC$11:$CC$1338,Calculs!$G$11:$G$1338,$B20) -> 4.8897152 | H20: ="" | I20: GES non attribué | M20: =SUMIFS(Calculs!$CC$11:$CC$1338,Calculs!$H$11:$H$1338,$H20) -> 166.46692
B21: Tous | E21: =SUM(E9:E20) -> 177.59168 | H21: Tous | K21: =SUM(K9:K20) -> 4000 | M21: =SUM(M9:M20) -> 177.59168 | T21: =COUNTIF(T9:T20,"oui") -> 2

Sheet Calculs
B1: Calculs | BQ1: Résultats
B3: # méthode | C3: Liste | D3: Description | E3: Date | F3: mois | G3: Site | H3: Produit | I3: Références | J3: Utilisation et Combustible | K3: Quantité combustible (équipements fixes) | M3: Type de véhicule et type de carburant | N3: Coûts en carburants | O3: Prix moyenne du carburant | P3: Année | Q3: Marque | R3: Modèle | S3: Transmission | T3: Distance parcourus | U3: Véhicule | V3: Consommation moyenne de carburant | W3: Quantité de carburant (Équipements mobiles) | Y3: Province | Z3: Consommation moyenne [kWh] | AA3: Estimation | AC3: Type d'équipement de réfrigéation | AD3: Type de réfrigérant | AE3: Quantité dans l'équipement | AF3: Fuites constaté par le frigoriste | AG3: Climatisation des véhicules (oui/non) | AH3: Réseaux électrique | AI3: Quantité d'électricité | AJ3: Intensité carbone du marché | AK3: Type d'aliment | AL3: Type de repas | AM3: Quantité | AO3: Événement | AP3: Mode de transport | AQ3: Consommation | AR3: Distance | AT3: Quantité de carburant | AU3: Nombre de passagers | AV3: Nombre de véhicules | AW3: Origine et destination | AX3: Aller et retour ? | AY3: Nombre de jours de travail par années | AZ3: Nombre de déplacements identiques | BA3: Type d'appareil numérique | BB3: Quantité | BC3: Type de réseau internet | BD3: Qunatité de données | BE3: Type de salle de serveurs | BF3: Superficie | BG3: Taille du papier | BH3: Proportion de papier recyclé | BI3: Quantité | BJ3: Type de traitement des eaux usées | BK3: Quantité | BQ3: Probabilité de fuite | BR3: Fuite estimé à partir des probabilité | BS3: Fuites calculée | BT3: PRP | BU3: Distances | BV3: Qte de carburant | BY3: CO2 | BZ3: CH4 | CA3: N2O | CB3: Total GES : | CE3: Total CO2 Biogénique : | CH3: Énergie équivalente
B5: 1.1A1 - Chauffage des bâtiments et équipements fixes
B7: Données d'activité | BQ7: Calculs et résultats
B8: # méthode | C8: Liste d'équipements ou de groupes d'équipements fixes | D8: Description | E8: Date | F8: mois | G8: Site | H8: Produit | I8: Références | J8: Utilisation et Combustible | K8: Quantité Totale | BY8: Émissions GES | CB8: Total GES : | CE8: Total CO2 Biogénique : | CH8: Énergie équivalente
BY9: CO2 | BZ9: CH4 | CA9: N2O
D10: (Facultatif) | E10: (Facultatif) | G10: (Facultatif) | H10: (Facultatif) | I10: (Facultatif) | J10: (Sélectionner) | K10: Qte | BY10: [gCO2e] | BZ10: [gCO2e] | CA10: [gCO2e] | CB10: [gCO2e] | CC10: [tCO2e] | CE10: [gCO2e] | CF10: [tCO2e] | CH10: [kWh]
B11: 1.1A1 | F11: =IF(E11=0,"",MONTH(E11)) | L11: =IFERROR(VLOOKUP(J11,FÉ!$B$10:$L$22,5,FALSE),"") | BY11: =IF($J11=0, ,VLOOKUP($J11,FÉ!$B$9:$K$22,8,FALSE)*$K11*PRP!$J$8) -> 0 | BZ11: =IF($J11=0, ,VLOOKUP($J11,FÉ!$B$9:$K$22,9,FALSE)*$K11*PRP!$J$9) -> 0 | CA11: =IF($J11=0, ,VLOOKUP($J11,FÉ!$B$9:$K$22,10,FALSE)*$K11*PRP!$J$10) -> 0 | CB11: =SUM(BY11:CA11) -> 0 | CC11: =CB11/(10^6) -> 0 | CE11: =IF(J11=FÉ!$B$12,K11* FÉ!$Q$12,) -> 0 | CF11: =CE11/(10^6) -> 0 | CH11: =IF($J11=0, ,VLOOKUP($J11,FÉ!$B$9:$K$22,7,FALSE))*K11 -> 0
B12: =B11 -> 1.1A1 | C12: Chaudière #1 | E12: 45658 | F12: =IF(E12=0,"",MONTH(E12)) -> 1 | G12: Usine #1 | H12: Balais | J12: Génératrice - Mazout [L] | K12: 1000 | L12: =IFERROR(VLOOKUP(J12,FÉ!$B$10:$L$22,5,FALSE),"") -> L | BY12: =IF($J12=0, ,VLOOKUP($J12,FÉ!$B$9:$K$22,8,FALSE)*$K12*PRP!$J$8) -> 2753000 | BZ12: =IF($J12=0, ,VLOOKUP($J12,FÉ!$B$9:$K$22,9,FALSE)*$K12*PRP!$J$9) -> 5364 | CA12: =IF($J12=0, ,VLOOKUP($J12,FÉ!$B$9:$K$22,10,FALSE)*$K12*PRP!$J$10) -> 8463 | CB12: =SUM(BY12:CA12) -> 2766827 | CC12: =CB12/(10^6) -> 2.766827 | CE12: =IF(J12=FÉ!$B$12,K12* FÉ!$Q$12,) -> 0 | CF12: =CE12/(10^6) -> 0 | CH12: =IF($J12=0, ,VLOOKUP($J12,FÉ!$B$9:$K$22,7,FALSE))*K12 -> 10770
B13: =B12 -> 1.1A1 | C13: Poêle à bois | F13: =IF(E13=0,"",MONTH(E13)) | G13: Bureau | J13: Chauffage - Bois [kg] | K13: 1500 | L13: =IFERROR(VLOOKUP(J13,FÉ!$B$10:$L$22,5,FALSE),"") -> kg | BY13: =IF($J13=0, ,VLOOKUP($J13,FÉ!$B$9:$K$22,8,FALSE)*$K13*PRP!$J$8) -> 0 | BZ13: =IF($J13=0, ,VLOOKUP($J13,FÉ!$B$9:$K$22,9,FALSE)*$K13*PRP!$J$9) -> 25747.2 | CA13: =IF($J13=0, ,VLOOKUP($J13,FÉ!$B$9:$K$22,10,FALSE)*$K13*PRP!$J$10) -> 31531.5 | CB13: =SUM(BY13:CA13) -> 57278.7 | CC13: =CB13/(10^6) -> 0.0572787 | CE13: =IF(J13=FÉ!$B$12,K13* FÉ!$Q$12,) -> 2698500 | CF13: =CE13/(10^6) -> 2.6985 | CH13: =IF($J13=0, ,VLOOKUP($J13,FÉ!$B$9:$K$22,7,FALSE))*K13 -> 7995
B14: =B13 -> 1.1A1 | F14: =IF(E14=0,"",MONTH(E14)) | G14: Usine #1 | J14: Chauffage - Propane [L] | K14: 1000 | L14: =IFERROR(VLOOKUP(J14,FÉ!$B$10:$L$22,5,FALSE),"") -> L | BY14: =IF($J14=0, ,VLOOKUP($J14,FÉ!$B$9:$K$22,8,FALSE)*$K14*PRP!$J$8) -> 1515000 | BZ14: =IF($J14=0, ,VLOOKUP($J14,FÉ!$B$9:$K$22,9,FALSE)*$K14*PRP!$J$9) -> 804.6 | CA14: =IF($J14=0, ,VLOOKUP($J14,FÉ!$B$9:$K$22,10,FALSE)*$K14*PRP!$J$10) -> 29484 | CB14: =SUM(BY14:CA14) -> 1545288.6 | CC14: =CB14/(10^6) -> 1.5452886 | CE14: =IF(J14=FÉ!$B$12,K14* FÉ!$Q$12,) -> 0 | CF14: =CE14/(10^6) -> 0 | CH14: =IF($J14=0, ,VLOOKUP($J14,FÉ!$B$9:$K$22,7,FALSE))*K14 -> 7030
B15: =B14 -> 1.1A1 | F15: =IF(E15=0,"",MONTH(E15)) | L15: =IFERROR(VLOOKUP(J15,FÉ!$B$10:$L$22,5,FALSE),"") | BY15: =IF($J15=0, ,VLOOKUP($J15,FÉ!$B$9:$K$22,8,FALSE)*$K15*PRP!$J$8) -> 0 | BZ15: =IF($J15=0, ,VLOOKUP($J15,FÉ!$B$9:$K$22,9,FALSE)*$K15*PRP!$J$9) -> 0 | CA15: =IF($J15=0, ,VLOOKUP($J15,FÉ!$B$9:$K$22,10,FALSE)*$K15*PRP!$J$10) -> 0 | CB15: =SUM(BY15:CA15) -> 0 | CC15: =CB15/(10^6) -> 0 | CE15: =IF(J15=FÉ!$B$12,K15* FÉ!$Q$12,) -> 0 | CF15: =CE15/(10^6) -> 0 | CH15: =IF($J15=0, ,VLOOKUP($J15,FÉ!$B$9:$K$22,7,FALSE))*K15 -> 0
B16: =B15 -> 1.1A1 | F16: =IF(E16=0,"",MONTH(E16)) | L16: =IFERROR(VLOOKUP(J16,FÉ!$B$10:$L$22,5,FALSE),"") | BY16: =IF($J16=0, ,VLOOKUP($J16,FÉ!$B$9:$K$22,8,FALSE)*$K16*PRP!$J$8) -> 0 | BZ16: =IF($J16=0, ,VLOOKUP($J16,FÉ!$B$9:$K$22,9,FALSE)*$K16*PRP!$J$9) -> 0 | CA16: =IF($J16=0, ,VLOOKUP($J16,FÉ!$B$9:$K$22,10,FALSE)*$K16*PRP!$J$10) -> 0 | CB16: =SUM(BY16:CA16) -> 0 | CC16: =CB16/(10^6) -> 0 | CE16: =IF(J16=FÉ!$B$12,K16* FÉ!$Q$12,) -> 0 | CF16: =CE16/(10^6) -> 0 | CH16: =IF($J16=0, ,VLOOKUP($J16,FÉ!$B$9:$K$22,7,FALSE))*K16 -> 0
B17: =B16 -> 1.1A1 | F17: =IF(E17=0,"",MONTH(E17)) | L17: =IFERROR(VLOOKUP(J17,FÉ!$B$10:$L$22,5,FALSE),"") | BY17: =IF($J17=0, ,VLOOKUP($J17,FÉ!$B$9:$K$22,8,FALSE)*$K17*PRP!$J$8) -> 0 | BZ17: =IF($J17=0, ,VLOOKUP($J17,FÉ!$B$9:$K$22,9,FALSE)*$K17*PRP!$J$9) -> 0 | CA17: =IF($J17=0, ,VLOOKUP($J17,FÉ!$B$9:$K$22,10,FALSE)*$K17*PRP!$J$10) -> 0 | CB17: =SUM(BY17:CA17) -> 0 | CC17: =CB17/(10^6) -> 0 | CE17: =IF(J17=FÉ!$B$12,K17* FÉ!$Q$12,) -> 0 | CF17: =CE17/(10^6) -> 0 | CH17: =IF($J17=0, ,VLOOKUP($J17,FÉ!$B$9:$K$22,7,FALSE))*K17 -> 0
B18: =B17 -> 1.1A1 | F18: =IF(E18=0,"",MONTH(E18)) | L18: =IFERROR(VLOOKUP(J18,FÉ!$B$10:$L$22,5,FALSE),"") | BY18: =IF($J18=0, ,VLOOKUP($J18,FÉ!$B$9:$K$22,8,FALSE)*$K18*PRP!$J$8) -> 0 | BZ18: =IF($J18=0, ,VLOOKUP($J18,FÉ!$B$9:$K$22,9,FALSE)*$K18*PRP!$J$9) -> 0 | CA18: =IF($J18=0, ,VLOOKUP($J18,FÉ!$B$9:$K$22,10,FALSE)*$K18*PRP!$J$10) -> 0 | CB18: =SUM(BY18:CA18) -> 0 | CC18: =CB18/(10^6) -> 0 | CE18: =IF(J18=FÉ!$B$12,K18* FÉ!$Q$12,) -> 0 | CF18: =CE18/(10^6) -> 0 | CH18: =IF($J18=0, ,VLOOKUP($J18,FÉ!$B$9:$K$22,7,FALSE))*K18 -> 0
B19: =B18 -> 1.1A1 | F19: =IF(E19=0,"",MONTH(E19)) | L19: =IFERROR(VLOOKUP(J19,FÉ!$B$10:$L$22,5,FALSE),"") | BY19: =IF($J19=0, ,VLOOKUP($J19,FÉ!$B$9:$K$22,8,FALSE)*$K19*PRP!$J$8) -> 0 | BZ19: =IF($J19=0, ,VLOOKUP($J19,FÉ!$B$9:$K$22,9,FALSE)*$K19*PRP!$J$9) -> 0 | CA19: =IF($J19=0, ,VLOOKUP($J19,FÉ!$B$9:$K$22,10,FALSE)*$K19*PRP!$J$10) -> 0 | CB19: =SUM(BY19:CA19) -> 0 | CC19: =CB19/(10^6) -> 0 | CE19: =IF(J19=FÉ!$B$12,K19* FÉ!$Q$12,) -> 0 | CF19: =CE19/(10^6) -> 0 | CH19: =IF($J19=0, ,VLOOKUP($J19,FÉ!$B$9:$K$22,7,FALSE))*K19 -> 0
B20: =B19 -> 1.1A1 | F20: =IF(E20=0,"",MONTH(E20)) | L20: =IFERROR(VLOOKUP(J20,FÉ!$B$10:$L$22,5,FALSE),"") | BY20: =IF($J20=0, ,VLOOKUP($J20,FÉ!$B$9:$K$22,8,FALSE)*$K20*PRP!$J$8) -> 0 | BZ20: =IF($J20=0, ,VLOOKUP($J20,FÉ!$B$9:$K$22,9,FALSE)*$K20*PRP!$J$9) -> 0 | CA20: =IF($J20=0, ,VLOOKUP($J20,FÉ!$B$9:$K$22,10,FALSE)*$K20*PRP!$J$10) -> 0 | CB20: =SUM(BY20:CA20) -> 0 | CC20: =CB20/(10^6) -> 0 | CE20: =IF(J20=FÉ!$B$12,K20* FÉ!$Q$12,) -> 0 | CF20: =CE20/(10^6) -> 0 | CH20: =IF($J20=0, ,VLOOKUP($J20,FÉ!$B$9:$K$22,7,FALSE))*K20 -> 0
B21: =B20 -> 1.1A1 | F21: =IF(E21=0,"",MONTH(E21)) | L21: =IFERROR(VLOOKUP(J21,FÉ!$B$10:$L$22,5,FALSE),"") | BY21: =IF($J21=0, ,VLOOKUP($J21,FÉ!$B$9:$K$22,8,FALSE)*$K21*PRP!$J$8) -> 0 | BZ21: =IF($J21=0, ,VLOOKUP($J21,FÉ!$B$9:$K$22,9,FALSE)*$K21*PRP!$J$9) -> 0 | CA21: =IF($J21=0, ,VLOOKUP($J21,FÉ!$B$9:$K$22,10,FALSE)*$K21*PRP!$J$10) -> 0 | CB21: =SUM(BY21:CA21) -> 0 | CC21: =CB21/(10^6) -> 0 | CE21: =IF(J21=FÉ!$B$12,K21* FÉ!$Q$12,) -> 0 | CF21: =CE21/(10^6) -> 0 | CH21: =IF($J21=0, ,VLOOKUP($J21,FÉ!$B$9:$K$22,7,FALSE))*K21 -> 0
B22: =B21 -> 1.1A1 | F22: =IF(E22=0,"",MONTH(E22)) | L22: =IFERROR(VLOOKUP(J22,FÉ!$B$10:$L$22,5,FALSE),"") | BY22: =IF($J22=0, ,VLOOKUP($J22,FÉ!$B$9:$K$22,8,FALSE)*$K22*PRP!$J$8) -> 0 | BZ22: =IF($J22=0, ,VLOOKUP($J22,FÉ!$B$9:$K$22,9,FALSE)*$K22*PRP!$J$9) -> 0 | CA22: =IF($J22=0, ,VLOOKUP($J22,FÉ!$B$9:$K$22,10,FALSE)*$K22*PRP!$J$10) -> 0 | CB22: =SUM(BY22:CA22) -> 0 | CC22: =CB22/(10^6) -> 0 | CE22: =IF(J22=FÉ!$B$12,K22* FÉ!$Q$12,) -> 0 | CF22: =CE22/(10^6) -> 0 | CH22: =IF($J22=0, ,VLOOKUP($J22,FÉ!$B$9:$K$22,7,FALSE))*K22 -> 0
B23: =B22 -> 1.1A1 | F23: =IF(E23=0,"",MONTH(E23)) | L23: =IFERROR(VLOOKUP(J23,FÉ!$B$10:$L$22,5,FALSE),"") | BY23: =IF($J23=0, ,VLOOKUP($J23,FÉ!$B$9:$K$22,8,FALSE)*$K23*PRP!$J$8) -> 0 | BZ23: =IF($J23=0, ,VLOOKUP($J23,FÉ!$B$9:$K$22,9,FALSE)*$K23*PRP!$J$9) -> 0 | CA23: =IF($J23=0, ,VLOOKUP($J23,FÉ!$B$9:$K$22,10,FALSE)*$K23*PRP!$J$10) -> 0 | CB23: =SUM(BY23:CA23) -> 0 | CC23: =CB23/(10^6) -> 0 | CE23: =IF(J23=FÉ!$B$12,K23* FÉ!$Q$12,) -> 0 | CF23: =CE23/(10^6) -> 0 | CH23: =IF($J23=0, ,VLOOKUP($J23,FÉ!$B$9:$K$22,7,FALSE))*K23 -> 0
B24: =B23 -> 1.1A1 | F24: =IF(E24=0,"",MONTH(E24)) | L24: =IFERROR(VLOOKUP(J24,FÉ!$B$10:$L$22,5,FALSE),"") | BY24: =IF($J24=0, ,VLOOKUP($J24,FÉ!$B$9:$K$22,8,FALSE)*$K24*PRP!$J$8) -> 0 | BZ24: =IF($J24=0, ,VLOOKUP($J24,FÉ!$B$9:$K$22,9,FALSE)*$K24*PRP!$J$9) -> 0 | CA24: =IF($J24=0, ,VLOOKUP($J24,FÉ!$B$9:$K$22,10,FALSE)*$K24*PRP!$J$10) -> 0 | CB24: =SUM(BY24:CA24) -> 0 | CC24: =CB24/(10^6) -> 0 | CE24: =IF(J24=FÉ!$B$12,K24* FÉ!$Q$12,) -> 0 | CF24: =CE24/(10^6) -> 0 | CH24: =IF($J24=0, ,VLOOKUP($J24,FÉ!$B$9:$K$22,7,FALSE))*K24 -> 0
B25: =B24 -> 1.1A1 | F25: =IF(E25=0,"",MONTH(E25)) | L25: =IFERROR(VLOOKUP(J25,FÉ!$B$10:$L$22,5,FALSE),"") | BY25: =IF($J25=0, ,VLOOKUP($J25,FÉ!$B$9:$K$22,8,FALSE)*$K25*PRP!$J$8) -> 0 | BZ25: =IF($J25=0, ,VLOOKUP($J25,FÉ!$B$9:$K$22,9,FALSE)*$K25*PRP!$J$9) -> 0 | CA25: =IF($J25=0, ,VLOOKUP($J25,FÉ!$B$9:$K$22,10,FALSE)*$K25*PRP!$J$10) -> 0 | CB25: =SUM(BY25:CA25) -> 0 | CC25: =CB25/(10^6) -> 0 | CE25: =IF(J25=FÉ!$B$12,K25* FÉ!$Q$12,) -> 0 | CF25: =CE25/(10^6) -> 0 | CH25: =IF($J25=0, ,VLOOKUP($J25,FÉ!$B$9:$K$22,7,FALSE))*K25 -> 0
B26: =B25 -> 1.1A1 | F26: =IF(E26=0,"",MONTH(E26)) | L26: =IFERROR(VLOOKUP(J26,FÉ!$B$10:$L$22,5,FALSE),"") | BY26: =IF($J26=0, ,VLOOKUP($J26,FÉ!$B$9:$K$22,8,FALSE)*$K26*PRP!$J$8) -> 0 | BZ26: =IF($J26=0, ,VLOOKUP($J26,FÉ!$B$9:$K$22,9,FALSE)*$K26*PRP!$J$9) -> 0 | CA26: =IF($J26=0, ,VLOOKUP($J26,FÉ!$B$9:$K$22,10,FALSE)*$K26*PRP!$J$10) -> 0 | CB26: =SUM(BY26:CA26) -> 0 | CC26: =CB26/(10^6) -> 0 | CE26: =IF(J26=FÉ!$B$12,K26* FÉ!$Q$12,) -> 0 | CF26: =CE26/(10^6) -> 0 | CH26: =IF($J26=0, ,VLOOKUP($J26,FÉ!$B$9:$K$22,7,FALSE))*K26 -> 0
... B30: =B29 -> 1.1A1 | F30: =IF(E30=0,"",MONTH(E30)) | L30: =IFERROR(VLOOKUP(J30,FÉ!$B$10:$L$22,5,FALSE),"") | BY30: =IF($J30=0, ,VLOOKUP($J30,FÉ!$B$9:$K$22,8,FALSE)*$K30*PRP!$J$8) -> 0 | BZ30: =IF($J30=0, ,VLOOKUP($J30,FÉ!$B$9:$K$22,9,FALSE)*$K30*PRP!$J$9) -> 0 | CA30: =IF($J30=0, ,VLOOKUP($J30,FÉ!$B$9:$K$22,10,FALSE)*$K30*PRP!$J$10) -> 0 | CB30: =SUM(BY30:CA30) -> 0 | CC30: =CB30/(10^6) -> 0 | CE30: =IF(J30=FÉ!$B$12,K30* FÉ!$Q$12,) -> 0 | CF30: =CE30/(10^6) -> 0 | CH30: =IF($J30=0, ,VLOOKUP($J30,FÉ!$B$9:$K$22,7,FALSE))*K30 -> 0
F31: =$B11 -> 1.1A1 | G31: =$B11 -> 1.1A1 | H31: =$B11 -> 1.1A1 | K31: =SUM(K11:K30) -> 3500 | BY31: =SUM(BY11:BY30) -> 4268000 | BZ31: =SUM(BZ11:BZ30) -> 31915.8 | CA31: =SUM(CA11:CA30) -> 69478.5 | CB31: =SUM(CB11:CB30) -> 4369394.3 | CC31: =SUM(CC11:CC30) -> 4.3693943 | CE31: =SUM(CE11:CE30) -> 2698500 | CF31: =SUM(CF11:CF30) -> 2.6985 | CH31: =SUM(CH11:CH30) -> 25795
B33: 1.2A1 - Véhicules (Par la quantité de combustible consommée)
B35: Données d'activité | BQ35: Calculs et résultats
B36: # méthode | C36: Liste des véhicules ou des groupes de véhicules | D36: Description | E36: Date | F36: mois | G36: Site | H36: Produit | I36: Références | M36: Type de véhicule et type de carburant | W36: Quantité Totale | BY36: Émissions GES | CB36: Total GES : | CE36: Total CO2 Biogénique : | CH36: Énergie équivalente
BY37: CO2 | BZ37: CH4 | CA37: N2O
D38: (Facultatif) | E38: (Facultatif) | G38: (Facultatif) | H38: (Facultatif) | I38: (Facultatif) | M38: (Sélectionner) | W38: Qte | BY38: [gCO2e] | BZ38: [gCO2e] | CA38: [gCO2e] | CB38: [gCO2e] | CC38: [tCO2e] | CE38: [gCO2e] | CF38: [tCO2e] | CH38: [kWh]
B39: 1.2A1 | F39: =IF(E39=0,"",MONTH(E39)) | X39: =IFERROR(VLOOKUP(M39,FÉ!$B$41:$L$59,5,FALSE),"") | BY39: =IF($M39=0, ,VLOOKUP($M39,FÉ!$B$41:$L$59,8,FALSE)*$W39*PRP!$J$8) -> 0 | BZ39: =IF($M39=0, ,VLOOKUP($M39,FÉ!$B$41:$L$59,9,FALSE)*$W39*PRP!$J$9) -> 0 | CA39: =IF($M39=0, ,VLOOKUP($M39,FÉ!$B$41:$L$59,10,FALSE)*$W39*PRP!$J$10) -> 0 | CB39: =SUM(BY39:CA39) -> 0 | CC39: =CB39/(10^6) -> 0 | CH39: =IF($M39=0, ,VLOOKUP($M39,FÉ!$B$41:$K$59,7,FALSE))*W39 -> 0
B40: =B39 -> 1.2A1 | F40: =IF(E40=0,"",MONTH(E40)) | G40: Bureau | M40: Voiture légère - Essence [L] | W40: 1000 | X40: =IFERROR(VLOOKUP(M40,FÉ!$B$41:$L$59,5,FALSE),"") -> L | BY40: =IF($M40=0, ,VLOOKUP($M40,FÉ!$B$41:$L$59,8,FALSE)*$W40*PRP!$J$8) -> 2307300 | BZ40: =IF($M40=0, ,VLOOKUP($M40,FÉ!$B$41:$L$59,9,FALSE)*$W40*PRP!$J$9) -> 3307.8 | CA40: =IF($M40=0, ,VLOOKUP($M40,FÉ!$B$41:$L$59,10,FALSE)*$W40*PRP!$J$10) -> 1911 | CB40: =SUM(BY40:CA40) -> 2312518.8 | CC40: =CB40/(10^6) -> 2.3125188 | CH40: =IF($M40=0, ,VLOOKUP($M40,FÉ!$B$41:$K$59,7,FALSE))*W40 -> 9690
B41: =B40 -> 1.2A1 | F41: =IF(E41=0,"",MONTH(E41)) | G41: Usine #2 | M41: Véhicule - Propane [lbs] | W41: 100 | X41: =IFERROR(VLOOKUP(M41,FÉ!$B$41:$L$59,5,FALSE),"") -> lbs | BY41: =IF($M41=0, ,VLOOKUP($M41,FÉ!$B$41:$L$59,8,FALSE)*$W41*PRP!$J$8) -> 137438.65 | BZ41: =IF($M41=0, ,VLOOKUP($M41,FÉ!$B$41:$L$59,9,FALSE)*$W41*PRP!$J$9) -> 1730.1848 | CA41: =IF($M41=0, ,VLOOKUP($M41,FÉ!$B$41:$L$59,10,FALSE)*$W41*PRP!$J$10) -> 693.45284 | CB41: =SUM(BY41:CA41) -> 139862.29 | CC41: =CB41/(10^6) -> 0.13986229 | CH41: =IF($M41=0, ,VLOOKUP($M41,FÉ!$B$41:$K$59,7,FALSE))*W41 -> 637.75163
B42: =B41 -> 1.2A1 | F42: =IF(E42=0,"",MONTH(E42)) | X42: =IFERROR(VLOOKUP(M42,FÉ!$B$41:$L$59,5,FALSE),"") | BY42: =IF($M42=0, ,VLOOKUP($M42,FÉ!$B$41:$L$59,8,FALSE)*$W42*PRP!$J$8) -> 0 | BZ42: =IF($M42=0, ,VLOOKUP($M42,FÉ!$B$41:$L$59,9,FALSE)*$W42*PRP!$J$9) -> 0 | CA42: =IF($M42=0, ,VLOOKUP($M42,FÉ!$B$41:$L$59,10,FALSE)*$W42*PRP!$J$10) -> 0 | CB42: =SUM(BY42:CA42) -> 0 | CC42: =CB42/(10^6) -> 0 | CH42: =IF($M42=0, ,VLOOKUP($M42,FÉ!$B$41:$K$59,7,FALSE))*W42 -> 0
B43: =B42 -> 1.2A1 | F43: =IF(E43=0,"",MONTH(E43)) | X43: =IFERROR(VLOOKUP(M43,FÉ!$B$41:$L$59,5,FALSE),"") | BY43: =IF($M43=0, ,VLOOKUP($M43,FÉ!$B$41:$L$59,8,FALSE)*$W43*PRP!$J$8) -> 0 | BZ43: =IF($M43=0, ,VLOOKUP($M43,FÉ!$B$41:$L$59,9,FALSE)*$W43*PRP!$J$9) -> 0 | CA43: =IF($M43=0, ,VLOOKUP($M43,FÉ!$B$41:$L$59,10,FALSE)*$W43*PRP!$J$10) -> 0 | CB43: =SUM(BY43:CA43) -> 0 | CC43: =CB43/(10^6) -> 0 | CH43: =IF($M43=0, ,VLOOKUP($M43,FÉ!$B$41:$K$59,7,FALSE))*W43 -> 0
B44: =B43 -> 1.2A1 | F44: =IF(E44=0,"",MONTH(E44)) | X44: =IFERROR(VLOOKUP(M44,FÉ!$B$41:$L$59,5,FALSE),"") | BY44: =IF($M44=0, ,VLOOKUP($M44,FÉ!$B$41:$L$59,8,FALSE)*$W44*PRP!$J$8) -> 0 | BZ44: =IF($M44=0, ,VLOOKUP($M44,FÉ!$B$41:$L$59,9,FALSE)*$W44*PRP!$J$9) -> 0 | CA44: =IF($M44=0, ,VLOOKUP($M44,FÉ!$B$41:$L$59,10,FALSE)*$W44*PRP!$J$10) -> 0 | CB44: =SUM(BY44:CA44) -> 0 | CC44: =CB44/(10^6) -> 0 | CH44: =IF($M44=0, ,VLOOKUP($M44,FÉ!$B$41:$K$59,7,FALSE))*W44 -> 0
B45: =B44 -> 1.2A1 | F45: =IF(E45=0,"",MONTH(E45)) | X45: =IFERROR(VLOOKUP(M45,FÉ!$B$41:$L$59,5,FALSE),"") | BY45: =IF($M45=0, ,VLOOKUP($M45,FÉ!$B$41:$L$59,8,FALSE)*$W45*PRP!$J$8) -> 0 | BZ45: =IF($M45=0, ,VLOOKUP($M45,FÉ!$B$41:$L$59,9,FALSE)*$W45*PRP!$J$9) -> 0 | CA45: =IF($M45=0, ,VLOOKUP($M45,FÉ!$B$41:$L$59,10,FALSE)*$W45*PRP!$J$10) -> 0 | CB45: =SUM(BY45:CA45) -> 0 | CC45: =CB45/(10^6) -> 0 | CH45: =IF($M45=0, ,VLOOKUP($M45,FÉ!$B$41:$K$59,7,FALSE))*W45 -> 0
B46: =B45 -> 1.2A1 | F46: =IF(E46=0,"",MONTH(E46)) | X46: =IFERROR(VLOOKUP(M46,FÉ!$B$41:$L$59,5,FALSE),"") | BY46: =IF($M46=0, ,VLOOKUP($M46,FÉ!$B$41:$L$59,8,FALSE)*$W46*PRP!$J$8) -> 0 | BZ46: =IF($M46=0, ,VLOOKUP($M46,FÉ!$B$41:$L$59,9,FALSE)*$W46*PRP!$J$9) -> 0 | CA46: =IF($M46=0, ,VLOOKUP($M46,FÉ!$B$41:$L$59,10,FALSE)*$W46*PRP!$J$10) -> 0 | CB46: =SUM(BY46:CA46) -> 0 | CC46: =CB46/(10^6) -> 0 | CH46: =IF($M46=0, ,VLOOKUP($M46,FÉ!$B$41:$K$59,7,FALSE))*W46 -> 0
B47: =B46 -> 1.2A1 | F47: =IF(E47=0,"",MONTH(E47)) | X47: =IFERROR(VLOOKUP(M47,FÉ!$B$41:$L$59,5,FALSE),"") | BY47: =IF($M47=0, ,VLOOKUP($M47,FÉ!$B$41:$L$59,8,FALSE)*$W47*PRP!$J$8) -> 0 | BZ47: =IF($M47=0, ,VLOOKUP($M47,FÉ!$B$41:$L$59,9,FALSE)*$W47*PRP!$J$9) -> 0 | CA47: =IF($M47=0, ,VLOOKUP($M47,FÉ!$B$41:$L$59,10,FALSE)*$W47*PRP!$J$10) -> 0 | CB47: =SUM(BY47:CA47) -> 0 | CC47: =CB47/(10^6) -> 0 | CH47: =IF($M47=0, ,VLOOKUP($M47,FÉ!$B$41:$K$59,7,FALSE))*W47 -> 0
B48: =B47 -> 1.2A1 | F48: =IF(E48=0,"",MONTH(E48)) | X48: =IFERROR(VLOOKUP(M48,FÉ!$B$41:$L$59,5,FALSE),"") | BY48: =IF($M48=0, ,VLOOKUP($M48,FÉ!$B$41:$L$59,8,FALSE)*$W48*PRP!$J$8) -> 0 | BZ48: =IF($M48=0, ,VLOOKUP($M48,FÉ!$B$41:$L$59,9,FALSE)*$W48*PRP!$J$9) -> 0 | CA48: =IF($M48=0, ,VLOOKUP($M48,FÉ!$B$41:$L$59,10,FALSE)*$W48*PRP!$J$10) -> 0 | CB48: =SUM(BY48:CA48) -> 0 | CC48: =CB48/(10^6) -> 0 | CH48: =IF($M48=0, ,VLOOKUP($M48,FÉ!$B$41:$K$59,7,FALSE))*W48 -> 0
...

Sheet Résultats
B1: Résultats
B3: =Calculs!B3 -> # méthode | C3: =Calculs!BY3 -> CO2 | D3: =Calculs!BZ3 -> CH4 | E3: =Calculs!CA3 -> N2O | F3: =Calculs!CB3 -> Total GES : | I3: =Calculs!CE3 -> Total CO2 Biogénique : | L3: =Calculs!CH3 -> Énergie équivalente
B4: =Calculs!B4 -> 0 | C4: =Calculs!BY4 -> 0 | D4: =Calculs!BZ4 -> 0 | E4: =Calculs!CA4 -> 0 | F4: =Calculs!CB4 -> 0 | G4: =Calculs!CC4 -> 0 | I4: =Calculs!CE4 -> 0 | J4: =Calculs!CF4 -> 0 | L4: =Calculs!CH4 -> 0
B5: =Calculs!B5 -> 1.1A1 - Chauffage des bâtiments et équipements fixes | C5: =Calculs!BY5 -> 0 | D5: =Calculs!BZ5 -> 0 | E5: =Calculs!CA5 -> 0 | F5: =Calculs!CB5 -> 0 | G5: =Calculs!CC5 -> 0 | I5: =Calculs!CE5 -> 0 | J5: =Calculs!CF5 -> 0 | L5: =Calculs!CH5 -> 0
B6: =Calculs!B6 -> 0 | C6: =Calculs!BY6 -> 0 | D6: =Calculs!BZ6 -> 0 | E6: =Calculs!CA6 -> 0 | F6: =Calculs!CB6 -> 0 | G6: =Calculs!CC6 -> 0 | I6: =Calculs!CE6 -> 0 | J6: =Calculs!CF6 -> 0 | L6: =Calculs!CH6 -> 0
B7: =Calculs!B7 -> Données d'activité | C7: =Calculs!BY7 -> 0 | D7: =Calculs!BZ7 -> 0 | E7: =Calculs!CA7 -> 0 | F7: =Calculs!CB7 -> 0 | G7: =Calculs!CC7 -> 0 | I7: =Calculs!CE7 -> 0 | J7: =Calculs!CF7 -> 0 | L7: =Calculs!CH7 -> 0
B8: =Calculs!B8 -> # méthode | C8: =Calculs!BY8 -> Émissions GES | D8: =Calculs!BZ8 -> 0 | E8: =Calculs!CA8 -> 0 | F8: =Calculs!CB8 -> Total GES : | G8: =Calculs!CC8 -> 0 | I8: =Calculs!CE8 -> Total CO2 Biogénique : | J8: =Calculs!CF8 -> 0 | L8: =Calculs!CH8 -> Énergie équivalente
B9: =Calculs!B9 -> 0 | C9: =Calculs!BY9 -> CO2 | D9: =Calculs!BZ9 -> CH4 | E9: =Calculs!CA9 -> N2O | F9: =Calculs!CB9 -> 0 | G9: =Calculs!CC9 -> 0 | I9: =Calculs!CE9 -> 0 | J9: =Calculs!CF9 -> 0 | L9: =Calculs!CH9 -> 0
B10: =Calculs!B10 -> 0 | C10: =Calculs!BY10 -> [gCO2e] | D10: =Calculs!BZ10 -> [gCO2e] | E10: =Calculs!CA10 -> [gCO2e] | F10: =Calculs!CB10 -> [gCO2e] | G10: =Calculs!CC10 -> [tCO2e] | I10: =Calculs!CE10 -> [gCO2e] | J10: =Calculs!CF10 -> [tCO2e] | L10: =Calculs!CH10 -> [kWh]
B11: =Calculs!B11 -> 1.1A1 | C11: =Calculs!BY11 -> 0 | D11: =Calculs!BZ11 -> 0 | E11: =Calculs!CA11 -> 0 | F11: =Calculs!CB11 -> 0 | G11: =Calculs!CC11 -> 0 | I11: =Calculs!CE11 -> 0 | J11: =Calculs!CF11 -> 0 | L11: =Calculs!CH11 -> 0
B12: =Calculs!B12 -> 1.1A1 | C12: =Calculs!BY12 -> 2753000 | D12: =Calculs!BZ12 -> 5364 | E12: =Calculs!CA12 -> 8463 | F12: =Calculs!CB12 -> 2766827 | G12: =Calculs!CC12 -> 2.766827 | I12: =Calculs!CE12 -> 0 | J12: =Calculs!CF12 -> 0 | L12: =Calculs!CH12 -> 10770
B13: =Calculs!B13 -> 1.1A1 | C13: =Calculs!BY13 -> 0 | D13: =Calculs!BZ13 -> 25747.2 | E13: =Calculs!CA13 -> 31531.5 | F13: =Calculs!CB13 -> 57278.7 | G13: =Calculs!CC13 -> 0.0572787 | I13: =Calculs!CE13 -> 2698500 | J13: =Calculs!CF13 -> 2.6985 | L13: =Calculs!CH13 -> 7995
B14: =Calculs!B14 -> 1.1A1 | C14: =Calculs!BY14 -> 1515000 | D14: =Calculs!BZ14 -> 804.6 | E14: =Calculs!CA14 -> 29484 | F14: =Calculs!CB14 -> 1545288.6 | G14: =Calculs!CC14 -> 1.5452886 | I14: =Calculs!CE14 -> 0 | J14: =Calculs!CF14 -> 0 | L14: =Calculs!CH14 -> 7030
B15: =Calculs!B15 -> 1.1A1 | C15: =Calculs!BY15 -> 0 | D15: =Calculs!BZ15 -> 0 | E15: =Calculs!CA15 -> 0 | F15: =Calculs!CB15 -> 0 | G15: =Calculs!CC15 -> 0 | I15: =Calculs!CE15 -> 0 | J15: =Calculs!CF15 -> 0 | L15: =Calculs!CH15 -> 0
... B210: =Calculs!B210 -> 0 | C210: =Calculs!BY210 -> 0 | D210: =Calculs!BZ210 -> 0 | E210: =Calculs!CA210 -> 0 | F210: =Calculs!CB210 -> 0 | G210: =Calculs!CC210 -> 0 | I210: =Calculs!CE210 -> 0 | J210: =Calculs!CF210 -> 0 | L210: =Calculs!CH210 -> 0
B211: =Calculs!#REF! -> #REF! | C211: =Calculs!#REF! -> #REF! | D211: =Calculs!#REF! -> #REF! | E211: =Calculs!#REF! -> #REF! | F211: =Calculs!#REF! -> #REF! | G211: =Calculs!#REF! -> #REF! | I211: =Calculs!#REF! -> #REF! | J211: =Calculs!#REF! -> #REF! | L211: =Calculs!#REF! -> #REF!
B212: =Calculs!#REF! -> #REF! | C212: =Calculs!#REF! -> #REF! | D212: =Calculs!#REF! -> #REF! | E212: =Calculs!#REF! -> #REF! | F212: =Calculs!#REF! -> #REF! | G212: =Calculs!#REF! -> #REF! | I212: =Calculs!#REF! -> #REF! | J212: =Calculs!#REF! -> #REF! | L212: =Calculs!#REF! -> #REF!
B213: =Calculs!#REF! -> #REF! | C213: =Calculs!#REF! -> #REF! | D213: =Calculs!#REF! -> #REF! | E213: =Calculs!#REF! -> #REF! | F213: =Calculs!#REF! -> #REF! | G213: =Calculs!#REF! -> #REF! | I213: =Calculs!#REF! -> #REF! | J213: =Calculs!#REF! -> #REF! | L213: =Calculs!#REF! -> #REF!
B214: =Calculs!#REF! -> #REF! | C214: =Calculs!#REF! -> #REF! | D214: =Calculs!#REF! -> #REF! | E214: =Calculs!#REF! -> #REF! | F214: =Calculs!#REF! -> #REF! | G214: =Calculs!#REF! -> #REF! | I214: =Calculs!#REF! -> #REF! | J214: =Calculs!#REF! -> #REF! | L214: =Calculs!#REF! -> #REF!
B215: =Calculs!#REF! -> #REF! | C215: =Calculs!#REF! -> #REF! | D215: =Calculs!#REF! -> #REF! | E215: =Calculs!#REF! -> #REF! | F215: =Calculs!#REF! -> #REF! | G215: =Calculs!#REF! -> #REF! | I215: =Calculs!#REF! -> #REF! | J215: =Calculs!#REF! -> #REF! | L215: =Calculs!#REF! -> #REF!
B216: =Calculs!#REF! -> #REF! | C216: =Calculs!#REF! -> #REF! | D216: =Calculs!#REF! -> #REF! | E216: =Calculs!#REF! -> #REF! | F216: =Calculs!#REF! -> #REF! | G216: =Calculs!#REF! -> #REF! | I216: =Calculs!#REF! -> #REF! | J216: =Calculs!#REF! -> #REF! | L216: =Calculs!#REF! -> #REF!
B217: =Calculs!#REF! -> #REF! | C217: =Calculs!#REF! -> #REF! | D217: =Calculs!#REF! -> #REF! | E217: =Calculs!#REF! -> #REF! | F217: =Calculs!#REF! -> #REF! | G217: =Calculs!#REF! -> #REF! | I217: =Calculs!#REF! -> #REF! | J217: =Calculs!#REF! -> #REF! | L217: =Calculs!#REF! -> #REF!
B218: =Calculs!#REF! -> #REF! | C218: =Calculs!#REF! -> #REF! | D218: =Calculs!#REF! -> #REF! | E218: =Calculs!#REF! -> #REF! | F218: =Calculs!#REF! -> #REF! | G218: =Calculs!#REF! -> #REF! | I218: =Calculs!#REF! -> #REF! | J218: =Calculs!#REF! -> #REF! | L218: =Calculs!#REF! -> #REF!
B219: =Calculs!#REF! -> #REF! | C219: =Calculs!#REF! -> #REF! | D219: =Calculs!#REF! -> #REF! | E219: =Calculs!#REF! -> #REF! | F219: =Calculs!#REF! -> #REF! | G219: =Calculs!#REF! -> #REF! | I219: =Calculs!#REF! -> #REF! | J219: =Calculs!#REF! -> #REF! | L219: =Calculs!#REF! -> #REF!
B220: =Calculs!#REF! -> #REF! | C220: =Calculs!#REF! -> #REF! | D220: =Calculs!#REF! -> #REF! | E220: =Calculs!#REF! -> #REF! | F220: =Calculs!#REF! -> #REF! | G220: =Calculs!#REF! -> #REF! | I220: =Calculs!#REF! -> #REF! | J220: =Calculs!#REF! -> #REF! | L220: =Calculs!#REF! -> #REF!
B221: =Calculs!#REF! -> #REF! | C221: =Calculs!#REF! -> #REF! | D221: =Calculs!#REF! -> #REF! | E221: =Calculs!#REF! -> #REF! | F221: =Calculs!#REF! -> #REF! | G221: =Calculs!#REF! -> #REF! | I221: =Calculs!#REF! -> #REF! | J221: =Calculs!#REF! -> #REF! | L221: =Calculs!#REF! -> #REF!
B222: =Calculs!#REF! -> #REF! | C222: =Calculs!#REF! -> #REF! | D222: =Calculs!#REF! -> #REF! | E222: =Calculs!#REF! -> #REF! | F222: =Calculs!#REF! -> #REF! | G222: =Calculs!#REF! -> #REF! | I222: =Calculs!#REF! -> #REF! | J222: =Calculs!#REF! -> #REF! | L222: =Calculs!#REF! -> #REF!
... B228: =Calculs!#REF! -> #REF! | C228: =Calculs!#REF! -> #REF! | D228: =Calculs!#REF! -> #REF! | E228: =Calculs!#REF! -> #REF! | F228: =Calculs!#REF! -> #REF! | G228: =Calculs!#REF! -> #REF! | I228: =Calculs!#REF! -> #REF! | J228: =Calculs!#REF! -> #REF! | L228: =Calculs!#REF! -> #REF!
B229: =Calculs!B265 -> 3.5A1 - Déplacements d'affaires en voiture | C229: =Calculs!BY265 -> 0 | D229: =Calculs!BZ265 -> 0 | E229: =Calculs!CA265 -> 0 | F229: =Calculs!CB265 -> 0 | G229: =Calculs!CC265 -> 0 | I229: =Calculs!CE265 -> 0 | J229: =Calculs!CF265 -> 0 | L229: =Calculs!CH265 -> 0
B230: =Calculs!B266 -> 0 | C230: =Calculs!BY266 -> 0 | D230: =Calculs!BZ266 -> 0 | E230: =Calculs!CA266 -> 0 | F230: =Calculs!CB266 -> 0 | G230: =Calculs!CC266 -> 0 | I230: =Calculs!CE266 -> 0 | J230: =Calculs!CF266 -> 0 | L230: =Calculs!CH266 -> 0
B231: =Calculs!B267 -> Données d'activité | C231: =Calculs!BY267 -> 0 | D231: =Calculs!BZ267 -> 0 | E231: =Calculs!CA267 -> 0 | F231: =Calculs!CB267 -> 0 | G231: =Calculs!CC267 -> 0 | I231: =Calculs!CE267 -> 0 | J231: =Calculs!CF267 -> 0 | L231: =Calculs!CH267 -> 0
B232: =Calculs!B268 -> # méthode | C232: =Calculs!BY268 -> Émissions GES | D232: =Calculs!BZ268 -> 0 | E232: =Calculs!CA268 -> 0 | F232: =Calculs!CB268 -> Total GES : | G232: =Calculs!CC268 -> 0 | I232: =Calculs!CE268 -> Total CO2 Biogénique : | J232: =Calculs!CF268 -> 0 | L232: =Calculs!CH268 -> Énergie équivalente
B233: =Calculs!B269 -> 0 | C233: =Calculs!BY269 -> CO2 | D233: =Calculs!BZ269 -> CH4 | E233: =Calculs!CA269 -> N2O | F233: =Calculs!CB269 -> 0 | G233: =Calculs!CC269 -> 0 | I233: =Calculs!CE269 -> 0 | J233: =Calculs!CF269 -> 0 | L233: =Calculs!CH269 -> 0
B234: =Calculs!B270 -> 0 | C234: =Calculs!BY270 -> [gCO2e] | D234: =Calculs!BZ270 -> [gCO2e] | E234: =Calculs!CA270 -> [gCO2e] | F234: =Calculs!CB270 -> [gCO2e] | G234: =Calculs!CC270 -> [tCO2e] | I234: =Calculs!CE270 -> [gCO2e] | J234: =Calculs!CF270 -> [tCO2e] | L234: =Calculs!CH270 -> [kWh]
B235: =Calculs!B271 -> 3.5A1 | C235: =Calculs!BY271 -> 0 | D235: =Calculs!BZ271 -> 0 | E235: =Calculs!CA271 -> 0 | F235: =Calculs!CB271 -> 0 | G235: =Calculs!CC271 -> 0 | I235: =Calculs!CE271 -> 0 | J235: =Calculs!CF271 -> 0 | L235: =Calculs!CH271 -> 0
B236: =Calculs!B272 -> 3.5A1 | C236: =Calculs!BY272 -> 576825 | D236: =Calculs!BZ272 -> 506.6 | E236: =Calculs!CA272 -> 13650 | F236: =Calculs!CB272 -> 590981.6 | G236: =Calculs!CC272 -> 0.5909816 | I236: =Calculs!CE272 -> 0 | J236: =Calculs!CF272 -> 0 | L236: =Calculs!CH272 -> 2422.5
B237: =Calculs!B273 -> 3.5A1 | C237: =Calculs!BY273 -> 1340250 | D237: =Calculs!BZ273 -> 759.9 | E237: =Calculs!CA273 -> 30030 | F237: =Calculs!CB273 -> 1371039.9 | G237: =Calculs!CC273 -> 1.3710399 | I237: =Calculs!CE273 -> 0 | J237: =Calculs!CF273 -> 0 | L237: =Calculs!CH273 -> 5320
B238: =Calculs!B274 -> 3.5A1 | C238: =Calculs!BY274 -> 0 | D238: =Calculs!BZ274 -> 0 | E238: =Calculs!CA274 -> 0 | F238: =Calculs!CB274 -> 0 | G238: =Calculs!CC274 -> 0 | I238: =Calculs!CE274 -> 0 | J238: =Calculs!CF274 -> 0 | L238: =Calculs!CH274 -> 0
B239: =Calculs!B275 -> 3.5A1 | C239: =Calculs!BY275 -> 0 | D239: =Calculs!BZ275 -> 0 | E239: =Calculs!CA275 -> 0 | F239: =Calculs!CB275 -> 0 | G239: =Calculs!CC275 -> 0 | I239: =Calculs!CE275 -> 0 | J239: =Calculs!CF275 -> 0 | L239: =Calculs!CH275 -> 0
B240: =Calculs!B276 -> 3.5A1 | C240: =Calculs!BY276 -> 0 | D240: =Calculs!BZ276 -> 0 | E240: =Calculs!CA276 -> 0 | F240: =Calculs!CB276 -> 0 | G240: =Calculs!CC276 -> 0 | I240: =Calculs!CE276 -> 0 | J240: =Calculs!CF276 -> 0 | L240: =Calculs!CH276 -> 0
...

Sheet Listes des méthodologies
B2: Liste des méthodologies de calculs | L2: Équivalent GHG PROTOCOL | N2: Mapping for Frontend programmation
B3: Catégorie | C3: Postes d'émissions | E3: Sources d'émissions | G3: Méthodologies
B4: [1@6] | C4: [1@22] | D4: Description | E4: [lettre] | F4: Description | G4: [no.] | H4: Description | I4: Code | J4: Notes | L4: Code | N4: Lines start | O4: Lines end
B5: Catégorie 1 | C5: 1.1 | D5: Émissions directes des sources de combustions fixes | E5: A | F5: Équipement fixe | G5: 1 | H5: Quantité de combustible comptabilisé à partir des factures | I5: 1.1A1 | L5: 1-1A1 | N5: =ROW(Debut_1A1)+1 -> 11 | O5: =ROW(Fin_1A1)-1 -> 30
G6: 2 | H6: Quantité de combustible estimé à partir de la moyenne de l'industrie | I6: 1A2 | L6: 1-1A2
C7: 1.2 | D7: Émissions directes des sources de combustions mobiles | E7: A | F7: Équipement mobile | G7: 1 | H7: Quantité de combustible comptabilisé à partir des factures | I7: 1.2A1 | J7: Liée à 10A1 | L7: 1-2A1 | N7: =ROW(Calculs!B38)+1 -> 39 | O7: =ROW(Calculs!B56)-1 -> 55
G8: 2 | H8: Par la distance parcourue (Consommation d'essence connue) | I8: 1.2A2 | L8: 1-2A2 | N8: =ROW(Calculs!B63)+1 -> 64 | O8: =ROW(Calculs!B74)-1 -> 73
G9: 3 | H9: À partir des coûts d'essence | I9: 1.2A3 | L9: 1-2A3 | N9: =ROW(Calculs!B81)+1 -> 82 | O9: =ROW(Calculs!B92)-1 -> 91
E10: B | F10: Véhicule | G10: 1 | H10: Par la distance parcourue (Consommation inconnue; Marque, modèle et année connus) | I10: 1.2B1 | J10: Liée à 10A3 | L10: 1-2B1 | N10: =ROW(Calculs!B99)+1 -> 100 | O10: =ROW(Calculs!B110)-1 -> 109
C11: 1.3 | D11: Émissions directes provenant des procédés et élevages d'animaux | E11: A | F11: Digestion entérique | G11: 1 | H11: Par tête | I11: 1.3A1 | J11: Liée à 3B2
E12: B | F12: Gestion du fumier | G12: 1 | H12: En kg par type d'élevage | I12: 1.3B1
G13: 2 | H13: Par tête | I13: 1.3B2 | J13: Liée à 3A1 (Nécessite 3A1)
E14: C | F14: Engrais azoté | G14: 1 | H14: Par quantité [kg] et % d'azote | I14: 1.3C1 | J14: Liée à 9F4
E15: D | F15: Procécéder | G15: 1 | H15: Nettoyage cryogénique | I15: 1.3D1 | J15: Liée à 9J1
C16: 1.4 | D16: Émissions fugitives directes (Réfrigérants) | E16: A | F16: Équipement fixe de climatisation et de réfrigération | G16: 1 | H16: Quantité rapporté par le frigoriste | I16: 1.4A1 | N16: =ROW(Calculs!B117)+1 -> 118 | O16: =ROW(Calculs!B128)-1 -> 127
G17: 2 | H17: Moyenne de l'industrie | I17: 1.4A2
E18: B | F18: Système de climatisation des véhicules | G18: 1 | H18: Moyenne de l'industrie | I18: 1.4B1 | J18: Liée à "Détails Entreprise" | N18: =ROW(Calculs!B135)+1 -> 136 | O18: =ROW(Calculs!B137)-1 -> 136
G19: 2 | H19: Données des véhicules | I19: 1.4B2 | N19: =ROW(Calculs!B144)+1 -> 145 | O19: =ROW(Calculs!B155)-1 -> 154
C20: 1.5 | D20: Émissions directes provenant de l'usage des sols (incluant agricoles) et de la foresterie | E20: A | F20: Déforestation | G20: 1 | H20: Par la surface et par le type de forêt | I20: 1.5A1 | J20: Liée à 5B1
E21: B | F21: Perte de séquestration | G21: 1 | H21: Par la surface et par le type de forêt (sur 100 ans) | I21: 1.5B1 | J21: Liée à 5A1 (Nécessite 5A1)
G22: 2 | H22: Par la surface et par le type de forêt (par année) | I22: 1.5B2
E23: C | F23: Plantation d'arbre | G23: 1 | H23: Nb d'arbres et année de plantation [kgCO2e capté/an] | I23: 1.5C1
G24: 2 | H24: Captation estimé sur X années | I24: 1.5C2
B25: Catégorie 2 | C25: 2.1 | D25: Émissions indirectes provenant de la consommation d'électricité | E25: A | F25: Consommation d'électricité (Location-based) | G25: 1 | H25: Quantité d'électricité comptabilisé à partir des factures | I25: 2.1A1 | L25: 2-1A1 | N25: =ROW(Calculs!B162)+1 -> 163 | O25: =ROW(Calculs!B173)-1 -> 172
G26: 2 | H26: Estimation à partir de la moyenne de l'industrie | I26: 2.1A2
E27: B | F27: Consommation d'électricité (Market-based) | G27: 1 | H27: Quantité d'électricité comptabilisé à partir des factures (avec certificat d'intensité carbone à l'appui) | I27: 2.1B1 | L27: 2-1B1 | N27: =ROW(Calculs!B180)+1 -> 181 | O27: =ROW(Calculs!B191)-1 -> 190
C28: 2.2 | D28: Émissions indirectes provenant de la consommation d'un réseau d'énergie (exclut l'électricité) | E28: A | F28: Importation d'énergie sous forme de chaleur | G28: 1 | H28: Quantité d'énergie produite et quantité d'énergie importée toutes deux connues | I28: 2.2A1 | L28: 2-2A1
G29: 2 | H29: Quantité de combustible attribuable à l'énergie importée | I29: 2.2A2 | L29: 2-2A2 | N29: =ROW(Calculs!B198)+1 -> 199 | O29: =ROW(Calculs!B210)-1 -> 209
G30: 3 | H30: Quantité d'énergie produite ESTIMÉE et quantité d'énergie importée connue | I30: 2.2A3
E31: B | F31: Importation d'énergie sous forme d'air comprimé | G31: 1 | H31: Quantité d'air comprimé acheté | I31: 2.2B1
B32: Catégorie 3 | C32: 3.1 | I32: 3.1A1 | N32: =ROW(Calculs!B216)+1 -> 217 | O32: =ROW(Calculs!B227)-1 -> 226
I33: 3.1A2
C34: 3.2 | I34: 3.2A1
I35: 3.2B1
C36: 3.3 | I36: 3.3A1
I37: 3.3A2
I38: 3.3A3
I39: 3.3B1
I40: 3.3B2
C41: 3.4 | I41: 3.4A1 | N41: =ROW(Calculs!B234)+1 -> 235 | O41: =ROW(Calculs!B245)-1 -> 244
...

Sheet PRP
B2: Global Warming Potential (GWP)
B5: GREENHOUSE GASES | J5: GWP | L5: References
J6: (100 years)
B7: Name | C7: chemical formula
B8: Carbon Dioxyde | C8: CO2 | J8: 1 | L8: IPCC (2021), AR6 Chapitre 7, table 7.15 (GWP-100)
B9: Methan | C9: CH4 | J9: 29.8 | L9: IPCC (2021), AR6 Chapitre 7, table 7.15 (GWP-100)
B10: nitrous oxide | C10: N2O | J10: 273 | L10: IPCC (2021), AR6 Chapitre 7, table 7.15 (GWP-100)
B11: PFC-14 | C11: CF4 | J11: 7380 | L11: IPCC (2021), AR6 Chapitre 7, table 7.15 (GWP-100)
B12: Sulfur hexafluoride | C12: SF6 | J12: 22800 | L12: NIR (2022), PT1, tableau A1-1, p.19
B15: REFRIGERANTS | J15: GWP | L15: References
D16: Blends | J16: (100 years)
B17: REFRIGERANTS | C17: Use for | D17: R-32 | E17: R-125 | F17: R-134a | G17: R-143a | H17: R-1234ze | I17: R-1234yf
B18: CFC-11 | J18: 6226 | L18: IPCC (2021), AR6 Chapitre 7, table 7.15 (GWP-100)
B19: CFC-12 | J19: 10910 | L19: HRAI (2019) Refrigerant Table Lexplanation and Glossary of Terms - https://www.hrai.ca/uploads/userfiles/files/refrigerant_table_June2019.pdf
B20: R-22 | C20: Ref. and air cond. | J20: 1810 | L20: HRAI (2019) Refrigerant Table Lexplanation and Glossary of Terms - https://www.hrai.ca/uploads/userfiles/files/refrigerant_table_June2019.pdf
B21: R-23 | J21: 14800 | L21: NIR (2022), PT1, tableau A1-1, p.19
B22: R-32 | C22: Air conditioning | J22: 771 | L22: IPCC (2021), AR6 Chapitre 7, table 7.15 (GWP-100)
B23: R-125 | J23: 3500 | L23: NIR (2022), PT1, tableau A1-1, p.19
B24: R-134a | C24: Air conditioning | J24: 1526 | L24: IPCC (2021), AR6 Chapitre 7, table 7.15 (GWP-100)
B25: R-143a | J25: 4470 | L25: NIR (2022), PT1, tableau A1-1, p.19
B26: R-404a | C26: Refrigeration | D26: 0 | E26: 0.44 | F26: 0.04 | G26: 0.52 | H26: 0 | I26: 0 | J26: =D26*$J$22+E26*$J$23+G26*$J$25+F26*$J$24+H26*$J$37+I26*$J$36 -> 3925.44 | L26: HRAI (2019) Refrigerant Table Lexplanation and Glossary of Terms - https://www.hrai.ca/uploads/userfiles/files/refrigerant_table_June2019.pdf
B27: R-407a | C27: Refrigeration | D27: 0.2 | E27: 0.4 | F27: 0.4 | G27: 0 | H27: 0 | I27: 0 | J27: =D27*$J$22+E27*$J$23+G27*$J$25+F27*$J$24+H27*$J$37+I27*$J$36 -> 2164.6 | L27: Chemours (2017) Freon 407C and 407A Properties, Uses, Storage, and Handling. https://www.freon.com/fr/-/media/files/freon/freon-r407c-r407a-push-bulletin.pdf?rev=d1d347da1ed04b9684663ebba7bc6a1f
B28: R-407c | C28: Refrigeration | D28: 0.23 | E28: 0.25 | F28: 0.52 | G28: 0 | H28: 0 | I28: 0 | J28: =D28*$J$22+E28*$J$23+G28*$J$25+F28*$J$24+H28*$J$37+I28*$J$36 -> 1845.85 | L28: HRAI (2019) Refrigerant Table Lexplanation and Glossary of Terms - https://www.hrai.ca/uploads/userfiles/files/refrigerant_table_June2019.pdf
B29: R-410a | C29: Air conditioning | D29: 0.5 | E29: 0.5 | F29: 0 | G29: 0 | H29: 0 | I29: 0 | J29: =D29*$J$22+E29*$J$23+G29*$J$25+F29*$J$24+H29*$J$37+I29*$J$36 -> 2135.5 | L29: HRAI (2019) Refrigerant Table Lexplanation and Glossary of Terms - https://www.hrai.ca/uploads/userfiles/files/refrigerant_table_June2019.pdf
B30: R-448a | C30: Refrigeration | D30: 0.26 | E30: 0.26 | F30: 0.21 | G30: 0 | H30: 0.07 | I30: 0.2 | J30: =D30*$J$22+E30*$J$23+G30*$J$25+F30*$J$24+H30*$J$37+I30*$J$36 -> 1431.72 | L30: HRAI (2019) Refrigerant Table Lexplanation and Glossary of Terms - https://www.hrai.ca/uploads/userfiles/files/refrigerant_table_June2019.pdf
B31: R-449a | C31: Refrigeration | D31: 0.243 | E31: 0.247 | F31: 0.257 | G31: 0 | H31: 0 | I31: 0.053 | J31: =D31*$J$22+E31*$J$23+G31*$J$25+F31*$J$24+H31*$J$37+I31*$J$36 -> 1444.247 | L31: National Refrigerants Inc. - https://refrigerants.com/product/r-449a/
B32: R-454B | C32: Refrigeration | D32: 0.689 | E32: 0 | F32: 0 | G32: 0 | H32: 0 | I32: 0.311 | J32: =D32*$J$22+E32*$J$23+G32*$J$25+F32*$J$24+H32*$J$37+I32*$J$36 -> 532.463 | L32: Climalife (n.-d.) R454B Specifications commerciales garanties. https://climalife.com/fr/product/r-454b/#:~:text=Le%20R%2D454B%20est%20un,est%20g%C3%A9n%C3%A9ralement%20mis%20en%20%C5%93uvre.
B33: R-513a | C33: Refrigeration | D33: 0 | E33: 0 | F33: 0.44 | G33: 0 | H33: 0 | I33: 0.56 | J33: =D33*$J$22+E33*$J$23+G33*$J$25+F33*$J$24+H33*$J$37+I33*$J$36 -> 673.68 | L33: HRAI (2019) Refrigerant Table Lexplanation and Glossary of Terms - https://www.hrai.ca/uploads/userfiles/files/refrigerant_table_June2019.pdf
B34: R-290 | C34: Refrigeration | J34: 3 | L34: Farmacold (n.d.) Réfrigérant R290. https://www.framacold.com/framacold-produit/39-r290-froid-domestique-et-commercial-#:~:text=Le%20propane%20pur%20R290%20est,nombreuses%20applications%20en%20froid%20commercial.&text=De%20tr%C3%A8s%20haute%20puret%C3%A9%20(%3E%2099,classement%20ASHRAE%20A3%20hautement%20inflammable.
B35: R-600a | C35: Refrigeration | J35: 3 | L35: Gasservei (n.d.) R-600a. https://gas-servei.com/fr/producto/r-600a/
B36: R-1234yf | C36: Air conditioning | J36: 4 | L36: HRAI (2019) Refrigerant Table Lexplanation and Glossary of Terms - https://www.hrai.ca/uploads/userfiles/files/refrigerant_table_June2019.pdf
B37: R-1234ze | J37: 0 | L37: HRAI (2019) Refrigerant Table Lexplanation and Glossary of Terms - https://www.hrai.ca/uploads/userfiles/files/refrigerant_table_June2019.pdf
B38: CO2 | C38: Refrigeration | J38: 1 | L38: IPCC (2021), AR6 Chapitre 7, table 7.15 (GWP-100)
B39: NH3 | C39: Refrigeration | J39: 0

Sheet FÉ
B2: Facteurs d'émissions
B6: 1 - Équipements fixes et Chauffage | G6: (Référence E) | H6: (Référence A) | L6: Total | S6: Références
G7: Conversion | H7: Conversion énergie | I7: CO2 | J7: CH4 | K7: N2O | L7: CO2éq | N7: CO2 Biogénique Anthropique | Q7: CO2 Biogénique Anthropique
B8: Liste | C8: Utilisation | D8: Carburant | F8: Unité | G8: [kg/L] | H8: [kWh/L] | I8: [gCO2/unité] | J8: [gCH4/unité] | K8: [gN2O/unité] | L8: [gCO2eq/unité] | N8: [gCO2eq/kg] | Q8: [gCO2eq/kg]
